## 异常

- 概念：程序在执行过程中，出现非正常情况，JVM非正常停止。**异常是一个类，产生异常就是创建一个异常对象并抛出，java处理的方式是中断处理**



- 注意：异常与语法错误不一样，语法错误无法运行



------



### 异常体系

- 异常体系图

![å¨è¿éæå¥å¾çæè¿°](https://img-blog.csdnimg.cn/20200326134301473.png?x-oss-process=image/watermark,type_ZmFuZ3poZW5naGVpdGk,shadow_10,text_aHR0cHM6Ly9ibG9nLmNzZG4ubmV0L21laXppemlMT0xPTE8=,size_16,color_FFFFFF,t_70)

- 解释

  - Throwable：所有异常或者错误类的超类

    
    - Error：错误一般是用于jvm或者是硬件引发的问题，所以我们一般不会通过代码去处理错误的
      - 比如：数据太大，超过内存限度

    

    - **Exception：异常，是需要通过代码去处理的。**
      - **RuntimeException ：运行时异常，可以不处理**
      - **非运行时异常：编译期异常，必须处理**



------



### 异常产生过程

- **注意点**

  - **假如一个方法中出现了异常，但如果没用调用它或者运行它，是不会报错的**

  ```java
  class test {
      void fun(){
          int[] arr={1,2,3};
          System.out.println(arr[4]);				//索引越界
      }
      public static void main(String[] args) {
          System.out.println(3);					//结果是3，可以正常运行
      }
  }
  ```
  - **假如调用或者运行的一个方法出现了异常，若没有解决方法，则会中断程序运行**

  ```java
  class test {
      void fun(){
          int[] arr={1,2,3};
          System.out.println(arr[4]);	    //索引越界
      }
      public static void main(String[] args) {
          test test = new test();	
          test.fun();						//调用了fun方法
          System.out.println(3);			//结果打印错误信息，不会输出3，程序中断了
      }
  }
  ```

  

- **产生过程**

  1. 在某一个被调用或者运行的方法中发现异常，会在此方法中先找寻是否有解决方法。
  2. 没有，将异常抛给调用者，没有调用者则传给JVM中断程序
  3. 若调用者也没有处理方法，继续将异常抛给调用者直到传给JVM处理

  ```java
  class test {
      void fun(){							//fun出错，判断没解决方法，异常抛给main方法
          int[] arr={1,2,3};
          System.out.println(arr[4]);
      }
      public static void main(String[] args) {
          test test = new test();			//main方法接受异常，判断没解决方法，异常抛给JVM处理
          test.fun();						
          System.out.println(3);			
      }
  }
  ```



- 过程图

![å¨è¿éæå¥å¾çæè¿°](https://img-blog.csdnimg.cn/20200326134313839.bmp?x-oss-process=image/watermark,type_ZmFuZ3poZW5naGVpdGk,shadow_10,text_aHR0cHM6Ly9ibG9nLmNzZG4ubmV0L21laXppemlMT0xPTE8=,size_16,color_FFFFFF,t_70)



------



### throw关键字

- **作用：在指定的方法中抛出指定的异常，常用于进行参数合法性校验**



- 格式：**throw new xxxException("异常产生原因");**



- 规则
  1. 必须写在方法内部
  2. xxxException必须是Exception对象或者其子类对象
  3. **throw抛出指定的异常对象，我们必须对此处理**
     - **如果是运行期异常，可以不用处理，默认交给JVM**
     - **如果是编译期异常，必须处理，要么用throws声明，要么用try-catch**

```java
运行期异常：
    
class test {
    void fun(int []arr){	
        if(arr == null){     							   //参数的合法性校对
          throw new NullPointerException("传递的参数为NULL");//空指针异常是运行期异常，可不用处理
        }
          System.out.println(33);						   //注：此时这里不会执行到
    }
    
    public static void main(String[] args) {
        int[] arr = null;
        test test = new test();
        test.fun(arr);							
    }
}
```

```java
编译期异常：
    
class test {
    void fun(){	
        throw new FileNotFoundException("文件找不到"); //这样会报错，因为是编译期异常必须处理	   
    }
}

    public static void main(String[] args) {
        test test = new test();
        test.fun();							
    }
}
```



------



### 异常处理的两种方式

#### throws声明

- 概念：异常处理的第一种方式，**意思是抛出异常，交给别的方法处理**



- 作用：当方法内部出现异常或者抛出异常时，**用throws处理，就是把异常对象声明抛出给该方法调用者**



- 规则

  1. 必须写在方法声明处

  2. throws抛出的必须是Exception对象或者其子类对象

  3. **如果方法内部抛出多个异常，必须声明抛出多个异常**

     - **如果多个异常有子父类关系，直接声明父类即可**

     ```java
     无子父类关系：
     
     class test {
         void fun(int i)throws FileNotFoundException,NullPointerException{ //声明多个异常
           if(i == 1) throw new FileNotFoundException("文件找不到"); 
           if(i == 0) throw new NullPointerException("空指针异常");
         }
     }
     ```

     ```java
     有子父类关系：
     
     class test {
         void fun(int i)throws Exception{							//声明父类异常即可
           if(i == 1) throw new FileNotFoundException("文件找不到"); 
           if(i == 0) throw new Exception("异常");
         }
     }
     ```

     

  4. **调用throws声明异常的方法，必须对异常进行处理**

     - **如果是运行期异常可以不用处理**

     - **要么继续throws声明继续抛出**
     - **要么try-catch**

     ```java
     class test {
         void fun(int i)throws FileNotFoundException{	   				 //编译期异常
             if(i == 0) throw new FileNotFoundException("文件找不到");
         }
     
         public static void main(String[] args) throws FileNotFoundException{ //必须声明
             test test = new test();
             test.fun(0);					//调用了声明抛出编译期异常的方法，必须处理	   
         }									//再次抛出或者try-catch
     }
     ```

     ```java
     class test {
         void fun(int i)throws NullPointerException{	    				//运行期异常
             if(i == 0) throw new NullPointerException("空指针异常");
         }
     
         public static void main(String[] args) {						//可以不处理
             test test = new test();
             test.fun(0);							   
         }
     }
     ```

     

#### try-catch捕捉

- 概念：异常的第二种处理方式，异常不再抛出而是进行处理



- **好处**
  - **可以把异常存进异常日志**
  - **即使出现异常，也不会中断处理，仍热可以执行程序**



- 格式

  ```java
  try{						//可能出现异常的代码
      .......			
  }catch(异常类型){			 //对异常的处理，操作不当异常处理会出错	
      ......
  }finally{					//无论是否出现异常都会执行的代码，常用于资源回收等
      ......
  }							
  ........					//异常处理成功后，仍热能执行下面程序
  ```



- **finally代码块**
  - 规则
    1. 无论是否有异常都会进行
    2. 不能单独进行，必须和try一起使用
    3. 用于释放资源





- **注意点**

  - **多个异常的处理**

    - 多次捕获多次处理

    ```java
    class Test {
        public static void main(String[] args) {
    		try {
                int[] arr = {1,2,3};
                System.out.println(arr[3]);
            }catch (ArrayIndexOutOfBoundsException e){
                System.out.println(e);
            }
     
            try{
                List<Integer> list = List.of(1, 2, 3);
                System.out.println(list.get(3));
            }catch (IndexOutOfBoundsException e){
                System.out.println(e);
            }
        }
    }
    ```

    - **一次捕获多次处理**
      - **注意： catch里的异常变量,如果有子父类关系,子类的异常变量必须写在上边,否则就会报错**

    ```java
    class Test {
        public static void main(String[] args) {
    		try {
                int[] arr = {1,2,3};
                List<Integer> list = List.of(1, 2, 3);
                System.out.println(list.get(3));
            }catch (ArrayIndexOutOfBoundsException e){	//父类异常
                System.out.println(e);
            }catch (IndexOutOfBoundsException e){		//子类异常
                System.out.println(e);
            }
        }
    }
    ```

    - **一次捕获一次处理**

    ```java
    class Test {
        public static void main(String[] args) {
    		try {
                int[] arr = {1,2,3};
                List<Integer> list = List.of(1, 2, 3);
                System.out.println(list.get(3)); 
            }catch (Exception e){					//所有异常对象的父类
                System.out.println(e);
            }
        }
    }
    ```

    

  - **finally代码块中有return，要避免**

    - **注意：一定会返回finally中的return结果**

    ```java
    class Test {
        public static void main(String[] args) {
            int a = getA();
            System.out.println(a);			//结果是100
        }
     
        public static int getA(){ 			//定义一个方法,返回变量a的值
            int a = 10;
            try{
                return a;
            }catch (Exception e){
                System.out.println(e);
            }finally {						  //一定会执行的代码
                a = 100;
                return a;
            }
     
        }
    }
    ```

    

  - **子父类异常**

    - **如果父类抛出了多个异常,子类重写父类方法时,抛出和父类相同的异常或者是父类异常的子类或者不抛出异常。**

    - **父类方法没有抛出异常，子类重写父类该方法时也不可抛出异常。此时子类产生该异常，只能捕获处理，不能声明抛出**

      ```java
      public class Fu {
          public void show01() throws NullPointerException,ClassCastException{}
          public void show02() throws IndexOutOfBoundsException{}
          public void show03() throws IndexOutOfBoundsException{}
          public void show04() throws Exception {}
      }
       
      class Zi extends Fu{
          //子类重写父类方法时,抛出和父类相同的异常
          public void show01() throws NullPointerException,ClassCastException{}
          //子类重写父类方法时,抛出父类异常的子类
          public void show02() throws ArrayIndexOutOfBoundsException{}
          //子类重写父类方法时,不抛出异常
          public void show03() {}
          //此时子类产生该异常，只能捕获处理，不能声明抛出
          public void show04()  {
              try {
                  throw  new Exception("编译期异常");
              } catch (Exception e) {
                  e.printStackTrace();
              }
          }
      }
      ```

      

------



### 异常常用方法

- 概念：Throwable中的方法，用于打印异常信息



- 异常图

  ![å¨è¿éæå¥å¾çæè¿°](https://img-blog.csdnimg.cn/2020032613423116.bmp?x-oss-process=image/watermark,type_ZmFuZ3poZW5naGVpdGk,shadow_10,text_aHR0cHM6Ly9ibG9nLmNzZG4ubmV0L21laXppemlMT0xPTE8=,size_16,color_FFFFFF,t_70)



- 方法 

  - toString方法：返回当前异常对象的完整类名+病态信息

    ```java
    class test {
        public static void main(String[] args) {
            try{
                int[] arr={1,2,3};
                System.out.println(arr[4]);
            }catch (Exception e) {
                System.out.println(e.toString());
            }
        }
    }
    
    ----------------------------------------------------------------------------------
     结果：java.lang.ArrayIndexOutOfBoundsException: Index 4 out of bounds for length 3
    ```

  - getMessage方法：返回的是创建Throwable传入的字符串信息

    ```java
    class test {
        public static void main(String[] args) {
            try{
                int[] arr={1,2,3};
                System.out.println(arr[4]);
            }catch (Exception e) {
                System.out.println(e.getMessage());
            }
        }
    }
    
    ----------------------------------------------------------------------------------
        结果：Index 4 out of bounds for length 3
    ```

  - **printStackTrace方法：打印异常的栈信息--异常引起的一系列出问题的代码位置信息**

    - **注：这个是最全面的**

    ```java
    class test {
        public static void main(String[] args) {
            try{
                int[] arr={1,2,3};
                System.out.println(arr[4]);
            }catch (Exception e) {
                e.printStackTrace();			//不用打印，他自己调用了
            }
        }
    }
    
    ----------------------------------------------------------------------------------
    结果：
    java.lang.ArrayIndexOutOfBoundsException: Index 4 out of bounds for length 3
    at com.chy.www.test.test.main(test.java:11)
    ```

    

------



### try组合方式

- **有异常要处理，但是没有资源要释放的**

  - try-catch

  ```java
   try{
       可能发生异常的代码
      }catch(捕获的异常类型 变量名){
      处理异常的代码
      }
  ```



- **既有异常要处理又要释放资源的代码**

  - try-catch-finally

  ```java
   try{
       可能发生异常的代码
      }catch(捕获的异常类型 变量名){
      处理异常的代码
      }finally{
      释放资源
   }
  ```

  

- **内部抛出的是运行时异常，并且有资源要被释放**

  - try-finally

  ```java
   try{
       可能发生异常的代码
      }finally{
      释放资源
   }
  ```

  